Workbook

Sheet Funnel
A3: Stage | B3: Stage name | C3: Candidate pathways (n) | D3: Cumulative retention (calc) | E3: Retention from previous stage (calc) | F3: Cumulative retention (paper) | G3: Retention from previous (paper) | H3: Check | I3: Primary evaluation criterion
A4: 1 | B4: AI-generated retrosynthetic pathways | C4: 48 | D4: =C4/$C$4 -> 1 | E4: — | F4: 1 | G4: — | H4: =IF(ROUND(D4,3)=F4,"OK","CHECK") -> OK | I4: Transformer prediction
A5: 2 | B5: Chemical plausibility filtering | C5: 31 | D5: =C5/$C$4 -> 0.64583333 | E5: =C5/C4 -> 0.64583333 | F5: 0.646 | G5: 0.646 | H5: =IF(AND(ROUND(D5,3)=F5,ROUND(E5,3)=G5),"OK","CHECK") -> OK | I5: Rule-based feasibility
A6: 3 | B6: DFT mechanistic evaluation | C6: 18 | D6: =C6/$C$4 -> 0.375 | E6: =C6/C5 -> 0.58064516 | F6: 0.375 | G6: 0.581 | H6: =IF(AND(ROUND(D6,3)=F6,ROUND(E6,3)=G6),"OK","CHECK") -> OK | I6: ΔG‡, HOMO–LUMO, Fukui index
A7: 4 | B7: Green chemistry screening | C7: 9 | D7: =C7/$C$4 -> 0.1875 | E7: =C7/C6 -> 0.5 | F7: 0.188 | G7: 0.5 | H7: =IF(AND(ROUND(D7,3)=F7,ROUND(E7,3)=G7),"OK","CHECK") -> OK | I7: Atom economy, PMI, E-factor
A8: 5 | B8: Multi-objective ranking | C8: 3 | D8: =C8/$C$4 -> 0.0625 | E8: =C8/C7 -> 0.33333333 | F8: 0.063 | G8: 0.333 | H8: =IF(AND(ROUND(D8,3)=F8,ROUND(E8,3)=G8),"OK","CHECK") -> OK | I8: Composite pathway score
A9: 6 | B9: Final selected pathway | C9: 1 | D9: =C9/$C$4 -> 0.020833333 | E9: =C9/C8 -> 0.33333333 | F9: 0.021 | G9: 0.333 | H9: =IF(AND(ROUND(D9,3)=F9,ROUND(E9,3)=G9),"OK","CHECK") -> OK | I9: Highest integrated score
B11: Derived statements in the text
B12: Statement | C12: Calculated | D12: Paper | E12: Note
B13: Pathways filtered out by plausibility step (fraction of 48) | C13: =1-C5/C4 -> 0.35416667 | D13: 0.354 | E13: Results section: "35.4% of the initial pathways were filtered out"
B14: Fraction of the 31 plausible routes remaining after DFT | C14: =C6/C5 -> 0.58064516 | D14: 0.581 | E14: Paper says DFT "narrowed down the number of candidates by half"
B15: DFT workload reduction vs. initial 48 | C15: =1-C6/C4 -> 0.625 | D15: 0.63 | E15: Paper: "decreasing the amount of DFT computations to about 63%" — 62.5% is the REDUCTION; the remaining share is 37.5%

Sheet AI_Confidence
A3: Metric | B3: Before filtering | C3: After filtering | D3: Change (calc) | E3: Source / note
A4: Pathways (n) | B4: 48 | C4: 31 | D4: =C4-B4 -> -17 | E4: Fig. 7B table; Table 15
A5: Mean confidence | B5: 0.79 | C5: 0.84 | D5: =C5-B5 -> 0.05 | E5: Fig. 7A/B; text "from 0.79 to 0.84"
A6: Median confidence | B6: 0.81 | C6: 0.85 | D6: =C6-B6 -> 0.04 | E6: Fig. 7B summary statistics
A7: Standard deviation | B7: 0.11 | C7: 0.08 | D7: =C7-B7 -> -0.03 | E7: Fig. 7B
A8: Minimum confidence | B8: 0.61 | C8: 0.65 | D8: =C8-B8 -> 0.04 | E8: Fig. 7B (after = 0.65). Text/Table 15 give 0.61–0.97 for the retained set — see Inconsistencies
A9: Maximum confidence | B9: 0.97 | C9: 0.97 | D9: =C9-B9 -> 0 | E9: Fig. 7B
A10: Pathways with confidence > 0.80 (n) | B10: 28 | C10: 22 | D10: =C10-B10 -> -6 | E10: Fig. 7A/B; Table 15 (22)
A11: Pathways with confidence ≤ 0.80 (n) | B11: 20 | C11: 9 | D11: =C11-B11 -> -11 | E11: Fig. 7B boxplot sample sizes
A12: % of pathways with confidence > 0.80 | B12: =B10/B4 -> 0.58333333 | C12: =C10/C4 -> 0.70967742 | D12: =C12-B12 -> 0.12634409 | E12: Paper: 58.3% → 71.0%, change +12.7% (paper subtracts the rounded values; unrounded difference is 12.6 points)
A13: Check: n(>0.80)+n(≤0.80) = total | B13: =B10+B11 -> 48 | C13: =C10+C11 -> 31 | D13: =IF(AND(B13=B4,C13=C4),"OK","CHECK") -> OK | E13: Consistency of reconstructed sub-group counts
A14: Retention rate | C14: =C4/B4 -> 0.64583333 | E14: Paper: 64.6%
A15: Pathways removed (total) | C15: =B4-C4 -> 17 | E15: 48 − 31
A16: …of which low-confidence (≤0.80) | C16: =B11-C11 -> 11 | E16: Derived
A17: …of which high-confidence (>0.80) | C17: =B10-C10 -> 6 | D17: =IF(C16+C17=C15,"OK","CHECK") -> OK | E17: Derived
A19: Table 15 / computing details
A20: Metric | B20: Value | E20: Source / note
A21: Initial candidate pathways | B21: 48 | E21: Table 15
A22: Pathways retained after filtering | B22: 31 | E22: Table 15
A23: Mean confidence ± SD (retained) | B23: =C5 -> 0.84 | E23: Table 15: 0.84 ± 0.08
A24: SD of confidence (retained) | B24: =C7 -> 0.08 | E24: Table 15
A25: Confidence range – min (Table 15) | B25: 0.61 | E25: Table 15 / text
A26: Confidence range – max (Table 15) | B26: 0.97 | E26: Table 15 / text
A27: Average generation time (s) | B27: 4.8 | E27: ± 0.6 s; RTX 4090 GPU + Intel Core i9 CPU
A28: Generation time SD (s) | B28: 0.6 | E28: Table 15
A29: Plausibility filtering time (s) | B29: <1 | E29: Table 15
A30: Beam size | B30: 10 | E30: Integrated framework section
A31: Cross-validation folds | B31: 5 | E31: Five-fold CV (internal validation)
A32: Mann-Whitney U (Fig. 7B) | B32: All pathways: p<0.01 (**); conf ≤0.80: p<0.001 (***); conf >0.80: ns | E32: Fig. 7B

Sheet DFT
A4: Pathway | B4: ΔG‡ (kcal/mol) | C4: HOMO–LUMO gap (eV) | D4: Fukui index f⁺ | E4: ΔGrxn (kcal/mol) | F4: Decision
A5: Route A | B5: 33.8 | C5: 5.61 | D5: 0.21 | E5: -8.2 | F5: Rejected
A6: Route B | B6: 25.4 | C6: 4.93 | D6: 0.28 | E6: -12.5 | F6: Retained
A7: Route C | B7: 18.6 | C7: 4.28 | D7: 0.34 | E7: -18.1 | F7: Selected
A8: Route D | B8: 22.1 | C8: 4.54 | D8: 0.3 | E8: -15.7 | F8: Retained
A9: Route E | B9: 22.7 | C9: 4.6 | D9: 0.25 | E9: -14.8 | F9: Retained
A12: Statistic | B12: Calculated | C12: Paper | D12: Note
A13: Min ΔG‡ (kcal/mol) | B13: =MIN(B5:B9) -> 18.6 | C13: 18.6 | D13: Paper range 18.6–33.8 for the 18 routes
A14: Max ΔG‡ (kcal/mol) | B14: =MAX(B5:B9) -> 33.8 | C14: 33.8
A15: Min HOMO–LUMO gap (eV) | B15: =MIN(C5:C9) -> 4.28 | C15: 4.28 | D15: Paper range 4.28–5.61 eV
A16: Max HOMO–LUMO gap (eV) | B16: =MAX(C5:C9) -> 5.61 | C16: 5.61
A17: Pearson r (gap vs ΔG‡) | B17: =CORREL(C5:C9,B5:B9) -> 0.99710284 | C17: -0.91 | D17: Fig. 8A reports r = −0.91 ("inverse"). The 5 published points give a POSITIVE r — see Inconsistencies
A18: R² (gap vs ΔG‡) | B18: =RSQ(B5:B9,C5:C9) -> 0.99421408 | C18: 0.82 | D18: Fig. 8A reports R² = 0.82
A19: Route D vs E: relative difference in f⁺ | B19: =(D8-D9)/D9 -> 0.2 | C19: 0.2 | D19: Paper: "almost 20% different"
A20: Route D vs E: ΔG‡ difference (kcal/mol) | B20: =B8-B9 -> -0.6 | C20: — | D20: Paper: both "about 22 kcal/mol"
A21: All ΔGrxn negative? | B21: =IF(MAX(E5:E9)<0,"Yes","No") -> Yes | C21: Yes | D21: Paper: all reaction free energies negative
A22: Route with highest f⁺ | B22: =INDEX(A5:A9,MATCH(MAX(D5:D9),D5:D9,0)) -> Route C | C22: Route C | D22: Paper: Route C, f⁺ = 0.34

Sheet Green
A3: Pathway | B3: Atom economy (%) | C3: PMI | D3: E-factor | E3: Environmental rank (paper) | F3: Decision | G3: Normalized sustainability score (Fig. 9B)
A4: Route A | B4: 58.4 | C4: 38.4 | D4: 31.2 | E4: 5 | F4: Rejected | G4: 0.42
A5: Route B | B5: 74.8 | C5: 24.6 | D5: 18.9 | E5: 3 | F5: Retained | G5: 0.73
A6: Route C | B6: 87.3 | C6: 16.8 | D6: 12.6 | E6: 1 | F6: Selected | G6: 0.94
A7: Route D | B7: 79.5 | C7: 22.7 | D7: 16.8 | E7: 2 | F7: Retained | G7: 0.82
A8: Route E | B8: 72.9 | C8: 26.3 | D8: 20.5 | E8: 4 | F8: Retained | G8: 0.69
A11: Assumptions for reconstruction (not in the paper)
A12: Ibuprofen MW (g/mol) | B12: 206.29 | C12: Standard molar mass of ibuprofen C13H18O2; used only to invert Eq. (1)
A13: Product mass basis (kg) | B13: 1 | C13: PMI and E-factor are per kg of isolated product (Eq. 2–3)
A15: Pathway | B15: Back-calculated ΣMW reactants (g/mol) = MW product / AE | C15: Check: AE recomputed from Eq. (1) (%) | D15: Total input mass (kg) = PMI × basis | E15: Waste mass (kg) = E-factor × basis | F15: PMI − E-factor (equals 1 for a closed mass balance) | G15: Rank by Fig. 9B score (calc) | H15: Rank matches paper?
A16: =A4 -> Route A | B16: =$B$12/(B4/100) -> 353.2363 | C16: =$B$12/B16*100 -> 58.4 | D16: =C4*$B$13 -> 38.4 | E16: =D4*$B$13 -> 31.2 | F16: =C4-D4 -> 7.2 | G16: =RANK(G4,$G$4:$G$8) -> 5 | H16: =IF(G16=E4,"OK","CHECK") -> OK
A17: =A5 -> Route B | B17: =$B$12/(B5/100) -> 275.78877 | C17: =$B$12/B17*100 -> 74.8 | D17: =C5*$B$13 -> 24.6 | E17: =D5*$B$13 -> 18.9 | F17: =C5-D5 -> 5.7 | G17: =RANK(G5,$G$4:$G$8) -> 3 | H17: =IF(G17=E5,"OK","CHECK") -> OK
A18: =A6 -> Route C | B18: =$B$12/(B6/100) -> 236.30011 | C18: =$B$12/B18*100 -> 87.3 | D18: =C6*$B$13 -> 16.8 | E18: =D6*$B$13 -> 12.6 | F18: =C6-D6 -> 4.2 | G18: =RANK(G6,$G$4:$G$8) -> 1 | H18: =IF(G18=E6,"OK","CHECK") -> OK
A19: =A7 -> Route D | B19: =$B$12/(B7/100) -> 259.48428 | C19: =$B$12/B19*100 -> 79.5 | D19: =C7*$B$13 -> 22.7 | E19: =D7*$B$13 -> 16.8 | F19: =C7-D7 -> 5.9 | G19: =RANK(G7,$G$4:$G$8) -> 2 | H19: =IF(G19=E7,"OK","CHECK") -> OK
A20: =A8 -> Route E | B20: =$B$12/(B8/100) -> 282.97668 | C20: =$B$12/B20*100 -> 72.9 | D20: =C8*$B$13 -> 26.3 | E20: =D8*$B$13 -> 20.5 | F20: =C8-D8 -> 5.8 | G20: =RANK(G8,$G$4:$G$8) -> 4 | H20: =IF(G20=E8,"OK","CHECK") -> OK
A23: Statement in text | B23: Calculated | C23: Paper | D23: Note
A24: Waste reduction Route A → Route C (E-factor) | B24: =(D4-D6)/D4 -> 0.59615385 | C24: 0.6 | D24: Paper: "almost 60%"
A25: PMI of Route A ÷ PMI of Route C | B25: =C4/C6 -> 2.2857143 | C25: 2 | D25: Paper: Route A "needed over double the amount of material" — true only vs. Route C (see also ÷B, ÷D, ÷E below)
A26: PMI Route A ÷ Route B | B26: =C4/C5 -> 1.5609756 | C26: —
A27: PMI Route A ÷ Route D | B27: =C4/C7 -> 1.69163 | C27: —
A28: PMI Route A ÷ Route E | B28: =C4/C8 -> 1.460076 | C28: —
A29: Atom economy range – max (%) | B29: =MAX(B4:B8) -> 87.3 | C29: 87.3 | D29: Case/Route C
A30: Atom economy range – min (%) | B30: =MIN(B4:B8) -> 58.4 | C30: 58.4 | D30: Route A
A31: PMI range – min | B31: =MIN(C4:C8) -> 16.8 | C31: 16.8 | D31: Paper: 16.8–38.4
A32: PMI range – max | B32: =MAX(C4:C8) -> 38.4 | C32: 38.4

Sheet Composite
A3: Criterion | B3: Weight | C3: Justification (Table 13)
A4: AI-assisted retrosynthetic prediction | B4: 0.3 | C4: Synthetic accessibility and route confidence
A5: Quantum chemical evaluation | B5: 0.3 | C5: Mechanistic feasibility and electronic reactivity
A6: Green chemistry assessment | B6: 0.4 | C6: Environmental sustainability and material efficiency
A7: Sum of weights (Σw = 1) | B7: =SUM(B4:B6) -> 1 | C7: =IF(ROUND(B7,6)=1,"OK","CHECK") -> OK
A9: Green descriptor (Table 11) | B9: Weight
A10: Atom economy | B10: 0.18
A11: Process mass intensity | B11: 0.12
A12: E-factor | B12: 0.1
A13: Sum (must equal green weight) | B13: =SUM(B10:B12) -> 0.4 | C13: =IF(ROUND(B13,6)=ROUND(B6,6),"OK","CHECK") -> OK
A15: Rank | B15: Pathway | C15: S reported (Table 18) | D15: AI score | E15: Quantum score | F15: Green score | G15: Final decision | H15: S recomputed (Eq. 7) | I15: Reported − recomputed | J15: Matches within ±0.005? | K15: Green score that would reproduce reported S (given AI & Quantum)
A16: 1 | B16: Route C | C16: 0.94 | D16: 0.89 | E16: 0.92 | F16: 0.96 | G16: Selected | H16: =$B$4*D16+$B$5*E16+$B$6*F16 -> 0.927 | I16: =C16-H16 -> 0.013 | J16: DIFF | K16: =(C16-$B$4*D16-$B$5*E16)/$B$6 -> 0.9925
A17: 2 | B17: Route D | C17: 0.82 | D17: 0.85 | E17: 0.78 | F17: 0.83 | G17: Retained | H17: =$B$4*D17+$B$5*E17+$B$6*F17 -> 0.821 | I17: =C17-H17 -> -0.001 | J17: =IF(ABS(I17)<=0.005,"OK","DIFF") -> OK | K17: =(C17-$B$4*D17-$B$5*E17)/$B$6 -> 0.8275
A18: 3 | B18: Route B | C18: 0.73 | D18: 0.81 | E18: 0.74 | F18: 0.64 | G18: Retained | H18: =$B$4*D18+$B$5*E18+$B$6*F18 -> 0.721 | I18: =C18-H18 -> 0.009 | J18: =IF(ABS(I18)<=0.005,"OK","DIFF") -> DIFF | K18: =(C18-$B$4*D18-$B$5*E18)/$B$6 -> 0.6625
A19: 4 | B19: Route E | C19: 0.69 | D19: 0.72 | E19: 0.7 | F19: 0.65 | G19: Retained | H19: =$B$4*D19+$B$5*E19+$B$6*F19 -> 0.686 | I19: =C19-H19 -> 0.004 | J19: =IF(ABS(I19)<=0.005,"OK","DIFF") -> OK | K19: =(C19-$B$4*D19-$B$5*E19)/$B$6 -> 0.66
A20: 5 | B20: Route A | C20: 0.41 | D20: 0.55 | E20: 0.38 | F20: 0.35 | G20: Rejected | H20: =$B$4*D20+$B$5*E20+$B$6*F20 -> 0.419 | I20: =C20-H20 -> -0.009 | J20: =IF(ABS(I20)<=0.005,"OK","DIFF") -> DIFF | K20: =(C20-$B$4*D20-$B$5*E20)/$B$6 -> 0.3275
A22: Range of S (reported) | B22: min | C22: =MIN(C16:C20) -> 0.41 | D22: max | E22: =MAX(C16:C20) -> 0.94 | F22: Paper: 0.41 to 0.94
A25: Contribution to final composite score (Fig. 10B / variance decomposition) | B25: Share
A26: AI prediction (retrosynthetic confidence) | B26: 0.27
A27: Quantum-chemical descriptors | B27: 0.31
A28: Green chemistry metrics | B28: 0.42
A29: Sum | B29: =SUM(B26:B28) -> 1 | C29: =IF(ROUND(B29,6)=1,"OK","CHECK") -> OK

Sheet Sensitivity
A3: Weighting coefficient | B3: Baseline (Table 20 / Fig. 12) | C3: −10% (calc) | D3: +10% (calc) | E3: Range low (paper) | F3: Range high (paper) | G3: Match | H3: Weight in Table 10/13
A4: AI | B4: 0.25 | C4: =B4*0.9 -> 0.225 | D4: =B4*1.1 -> 0.275 | E4: 0.225 | F4: 0.275 | G4: =IF(AND(ROUND(C4,3)=E4,ROUND(D4,3)=F4),"OK","CHECK") -> OK | H4: 0.3
A5: Quantum | B5: 0.35 | C5: =B5*0.9 -> 0.315 | D5: =B5*1.1 -> 0.385 | E5: 0.315 | F5: 0.385 | G5: =IF(AND(ROUND(C5,3)=E5,ROUND(D5,3)=F5),"OK","CHECK") -> OK | H5: 0.3
A6: Green chemistry | B6: 0.4 | C6: =B6*0.9 -> 0.36 | D6: =B6*1.1 -> 0.44 | E6: 0.36 | F6: 0.44 | G6: =IF(AND(ROUND(C6,3)=E6,ROUND(D6,3)=F6),"OK","CHECK") -> OK | H6: 0.4
A7: Sum | B7: =SUM(B4:B6) -> 1 | H7: =SUM(H4:H6) -> 1
A10: Outcome (Table 20) | B10: Baseline | C10: Range low | D10: Range high | E10: Calc low | F10: Calc high | G10: Note
A11: Spearman's ρ | B11: 0.96 | C11: 0.93 | D11: 0.98 | G11: Fig. 12B: mean 0.96 ± 0.015 over 20 LHS scenarios, min 0.93, max 0.98
A12: Composite score Route C | B12: 0.94 | C12: 0.922 | D12: 0.958 | E12: =B12-B13 -> 0.922 | F12: =B12+B13 -> 0.958 | G12: Reconstruction: range = baseline ± SD (0.94 ± 0.018) reproduces 0.922–0.958
A13: Average score SD (Route C, 20 LHS sets) | B13: 0.018
A14: Spearman SD (Fig. 12B) | B14: 0.015
A15: Number of LHS weight sets | B15: 20
A17: PCA (Fig. 5A) | B17: Explained variance
A18: PC1 | B18: 0.583
A19: PC2 | B19: 0.247
A20: PC1 + PC2 | B20: =B18+B19 -> 0.83
A22: Fig. 5B: Spearman rank correlation (approx., read from bars) | B22: −10% | C22: Baseline | D22: +10%
A23: AI (0.30) | B23: 0.941 | C23: 1 | D23: 0.947
A24: Quantum (0.30) | B24: 0.936 | C24: 1 | D24: 0.944
A25: Green (0.40) | B25: 0.932 | C25: 1 | D25: 0.939
A28: Fig. 12A composite scores (approx., read from figure labels) | B28: Green −10% (AI +5%, Q +5%) | C28: AI −10% (Green +5%, Q +5%) | D28: Baseline (0.25/0.35/0.40) | E28: Quantum −10% (AI +5%, Green +5%) | F28: All +10%*
A29: Route C | B29: 0.922 | C29: 0.93 | D29: 0.94 | E29: 0.95 | F29: 0.958
A30: Route D | B30: 0.76 | C30: 0.78 | D30: 0.8 | E30: 0.82 | F30: 0.835
A31: Route B | B31: 0.69 | C31: 0.71 | D31: 0.73 | E31: 0.748 | F31: 0.762
A32: Route E | B32: 0.62 | C32: 0.64 | D32: 0.66 | E32: 0.675 | F32: 0.69
A33: Route A | B33: 0.36 | C33: 0.38 | D33: 0.41 | E33: 0.435 | F33: 0.45
A34: Rank order of Route C is first in every scenario | B34: =IF(AND(B29>MAX(B30:B33),C29>MAX(C30:C33),D29>MAX(D30:D33),E29>MAX(E30:E33),F29>MAX(F30:F33)),"Yes","No") -> Yes

Sheet Normalization
A4: Pathway | B4: Atom economy (benefit, Eq.5) | C4: PMI (cost, Eq.6) | D4: E-factor (cost, Eq.6) | E4: ΔG‡ (cost, Eq.6) | F4: HOMO–LUMO gap (cost, Eq.6) | G4: Fukui f⁺ (benefit, Eq.5)
A5: =Green!A4 -> Route A | B5: =(Green!B4-MIN(Green!B$4:B$8))/(MAX(Green!B$4:B$8)-MIN(Green!B$4:B$8)) -> 0 | C5: =(MAX(Green!C$4:C$8)-Green!C4)/(MAX(Green!C$4:C$8)-MIN(Green!C$4:C$8)) -> 0 | D5: =(MAX(Green!D$4:D$8)-Green!D4)/(MAX(Green!D$4:D$8)-MIN(Green!D$4:D$8)) -> 0 | E5: =(MAX(DFT!B$5:B$9)-DFT!B5)/(MAX(DFT!B$5:B$9)-MIN(DFT!B$5:B$9)) -> 0 | F5: =(MAX(DFT!C$5:C$9)-DFT!C5)/(MAX(DFT!C$5:C$9)-MIN(DFT!C$5:C$9)) -> 0 | G5: =(DFT!D5-MIN(DFT!D$5:D$9))/(MAX(DFT!D$5:D$9)-MIN(DFT!D$5:D$9)) -> 0
A6: =Green!A5 -> Route B | B6: =(Green!B5-MIN(Green!B$4:B$8))/(MAX(Green!B$4:B$8)-MIN(Green!B$4:B$8)) -> 0.56747405 | C6: =(MAX(Green!C$4:C$8)-Green!C5)/(MAX(Green!C$4:C$8)-MIN(Green!C$4:C$8)) -> 0.63888889 | D6: =(MAX(Green!D$4:D$8)-Green!D5)/(MAX(Green!D$4:D$8)-MIN(Green!D$4:D$8)) -> 0.66129032 | E6: =(MAX(DFT!B$5:B$9)-DFT!B6)/(MAX(DFT!B$5:B$9)-MIN(DFT!B$5:B$9)) -> 0.55263158 | F6: =(MAX(DFT!C$5:C$9)-DFT!C6)/(MAX(DFT!C$5:C$9)-MIN(DFT!C$5:C$9)) -> 0.5112782 | G6: =(DFT!D6-MIN(DFT!D$5:D$9))/(MAX(DFT!D$5:D$9)-MIN(DFT!D$5:D$9)) -> 0.53846154
A7: =Green!A6 -> Route C | B7: =(Green!B6-MIN(Green!B$4:B$8))/(MAX(Green!B$4:B$8)-MIN(Green!B$4:B$8)) -> 1 | C7: =(MAX(Green!C$4:C$8)-Green!C6)/(MAX(Green!C$4:C$8)-MIN(Green!C$4:C$8)) -> 1 | D7: =(MAX(Green!D$4:D$8)-Green!D6)/(MAX(Green!D$4:D$8)-MIN(Green!D$4:D$8)) -> 1 | E7: =(MAX(DFT!B$5:B$9)-DFT!B7)/(MAX(DFT!B$5:B$9)-MIN(DFT!B$5:B$9)) -> 1 | F7: =(MAX(DFT!C$5:C$9)-DFT!C7)/(MAX(DFT!C$5:C$9)-MIN(DFT!C$5:C$9)) -> 1 | G7: =(DFT!D7-MIN(DFT!D$5:D$9))/(MAX(DFT!D$5:D$9)-MIN(DFT!D$5:D$9)) -> 1
A8: =Green!A7 -> Route D | B8: =(Green!B7-MIN(Green!B$4:B$8))/(MAX(Green!B$4:B$8)-MIN(Green!B$4:B$8)) -> 0.73010381 | C8: =(MAX(Green!C$4:C$8)-Green!C7)/(MAX(Green!C$4:C$8)-MIN(Green!C$4:C$8)) -> 0.72685185 | D8: =(MAX(Green!D$4:D$8)-Green!D7)/(MAX(Green!D$4:D$8)-MIN(Green!D$4:D$8)) -> 0.77419355 | E8: =(MAX(DFT!B$5:B$9)-DFT!B8)/(MAX(DFT!B$5:B$9)-MIN(DFT!B$5:B$9)) -> 0.76973684 | F8: =(MAX(DFT!C$5:C$9)-DFT!C8)/(MAX(DFT!C$5:C$9)-MIN(DFT!C$5:C$9)) -> 0.80451128 | G8: =(DFT!D8-MIN(DFT!D$5:D$9))/(MAX(DFT!D$5:D$9)-MIN(DFT!D$5:D$9)) -> 0.69230769
A9: =Green!A8 -> Route E | B9: =(Green!B8-MIN(Green!B$4:B$8))/(MAX(Green!B$4:B$8)-MIN(Green!B$4:B$8)) -> 0.5017301 | C9: =(MAX(Green!C$4:C$8)-Green!C8)/(MAX(Green!C$4:C$8)-MIN(Green!C$4:C$8)) -> 0.56018519 | D9: =(MAX(Green!D$4:D$8)-Green!D8)/(MAX(Green!D$4:D$8)-MIN(Green!D$4:D$8)) -> 0.57526882 | E9: =(MAX(DFT!B$5:B$9)-DFT!B9)/(MAX(DFT!B$5:B$9)-MIN(DFT!B$5:B$9)) -> 0.73026316 | F9: =(MAX(DFT!C$5:C$9)-DFT!C9)/(MAX(DFT!C$5:C$9)-MIN(DFT!C$5:C$9)) -> 0.7593985 | G9: =(DFT!D9-MIN(DFT!D$5:D$9))/(MAX(DFT!D$5:D$9)-MIN(DFT!D$5:D$9)) -> 0.30769231

Sheet Generalization
A3: API | B3: Initial pathways | C3: Final pathway | D3: Composite score | E3: ΔG‡ (kcal/mol) | F3: Atom economy (%) | G3: PMI | H3: E-factor | I3: PMI − E-factor | J3: Back-calc. ΣMW reactants per MW product
A4: Ibuprofen | B4: 48 | C4: Route C | D4: 0.94 | E4: 18.6 | F4: 87.3 | G4: 16.8 | H4: 12.6 | I4: =G4-H4 -> 4.2 | J4: =100/F4 -> 1.1454754
A5: Naproxen | B5: 45 | C5: Route B | D5: 0.91 | E5: 19.8 | F5: 84.5 | G5: 18.1 | H5: 13.9 | I5: =G5-H5 -> 4.2 | J5: =100/F5 -> 1.183432
A6: Paracetamol | B6: 41 | C6: Route A | D6: 0.89 | E6: 20.4 | F6: 82.8 | G6: 19.5 | H6: 15.2 | I6: =G6-H6 -> 4.3 | J6: =100/F6 -> 1.2077295
A8: Check vs other sheets (ibuprofen) | B8: =IF(AND(D4=Composite!C16,E4=DFT!B7,F4=Green!B6,G4=Green!C6,H4=Green!D6),"OK","CHECK") -> OK
A10: Other facts
A11: AI path generation time per compound | B11: < 5 s | C11: Text
A12: DFT share of total computation time | B12: 0.92 | C12: Text
A13: Reduction in DFT computations (text) | B13: 0.63 | C13: Text: "about 63%" — see Funnel sheet
A14: Same framework/weights used for all APIs | B14: Yes | C14: No re-tuning
A16: Note: column J is derived (100/AE) — it equals ΣMW reactants ÷ MW product implied by the atom-economy value.

Sheet Pathways_48
A1: 48
A3: Screening thresholds (assumptions)
A4: DFT filter: max ΔG‡ (kcal/mol) | B4: 35 | C4: Assumed cut-off; paper only reports that survivors span 18.6–33.8
A5: DFT filter: max HOMO–LUMO gap (eV) | B5: 5.65 | C5: Assumed cut-off; survivors span 4.28–5.61
A6: Green filter: min atom economy (%) | B6: 58 | C6: Assumed cut-off; retained routes span 58.4–87.3
A7: Green filter: max PMI | B7: 40 | C7: Assumed cut-off; retained routes span 16.8–38.4
A8: Green filter: max E-factor | B8: 32 | C8: Assumed cut-off; retained routes span 12.6–31.2
A11: Pathway ID | B11: Route label (paper) | C11: AI confidence | D11: Passed plausibility filter (1/0) | E11: ΔG‡ (kcal/mol) | F11: HOMO–LUMO gap (eV) | G11: Fukui f⁺ | H11: ΔGrxn (kcal/mol) | I11: Passed DFT stage (calc) | J11: Atom economy (%) | K11: PMI | L11: E-factor | M11: Passed green screening (calc) | N11: AI score (normalized) | O11: Quantum score (normalized) | P11: Green score (normalized) | Q11: Composite S | R11: Rank among 9 green survivors | S11: In top 3 (calc) | T11: Final selected (calc) | U11: Furthest stage reached
A12: P01 | B12: Route A | C12: 0.85 | D12: 1 | E12: =DFT!B5 -> 33.8 | F12: =DFT!C5 -> 5.61 | G12: =DFT!D5 -> 0.21 | H12: =DFT!E5 -> -8.2 | I12: =IF(AND(D12=1,ISNUMBER(E12),E12<=$B$4,F12<=$B$5),1,0) -> 1 | J12: =Green!B4 -> 58.4 | K12: =Green!C4 -> 38.4 | L12: =Green!D4 -> 31.2 | M12: =IF(AND(I12=1,ISNUMBER(J12),J12>=$B$6,K12<=$B$7,L12<=$B$8),1,0) -> 1 | N12: =Composite!D20 -> 0.55 | O12: =Composite!E20 -> 0.38 | P12: =Composite!F20 -> 0.35 | Q12: =Composite!C20 -> 0.41 | R12: =IF(M12=1,RANK(Q12,$Q$12:$Q$59),"") -> 9 | S12: =IF(M12=1,IF(R12<=3,1,0),0) -> 0 | T12: =IF(M12=1,IF(R12=1,1,0),0) -> 0 | U12: =IF(T12=1,"Selected",IF(S12=1,"Top 3",IF(M12=1,"Green screening",IF(I12=1,"DFT stage",IF(D12=1,"Plausibility","AI only"))))) -> Green screening
A13: P02 | B13: Route B | C13: 0.91 | D13: 1 | E13: =DFT!B6 -> 25.4 | F13: =DFT!C6 -> 4.93 | G13: =DFT!D6 -> 0.28 | H13: =DFT!E6 -> -12.5 | I13: =IF(AND(D13=1,ISNUMBER(E13),E13<=$B$4,F13<=$B$5),1,0) -> 1 | J13: =Green!B5 -> 74.8 | K13: =Green!C5 -> 24.6 | L13: =Green!D5 -> 18.9 | M13: =IF(AND(I13=1,ISNUMBER(J13),J13>=$B$6,K13<=$B$7,L13<=$B$8),1,0) -> 1 | N13: =Composite!D18 -> 0.81 | O13: =Composite!E18 -> 0.74 | P13: =Composite!F18 -> 0.64 | Q13: =Composite!C18 -> 0.73 | R13: =IF(M13=1,RANK(Q13,$Q$12:$Q$59),"") -> 3 | S13: =IF(M13=1,IF(R13<=3,1,0),0) -> 1 | T13: =IF(M13=1,IF(R13=1,1,0),0) -> 0 | U13: =IF(T13=1,"Selected",IF(S13=1,"Top 3",IF(M13=1,"Green screening",IF(I13=1,"DFT stage",IF(D13=1,"Plausibility","AI only"))))) -> Top 3
A14: P03 | B14: Route C | C14: 0.97 | D14: 1 | E14: =DFT!B7 -> 18.6 | F14: =DFT!C7 -> 4.28 | G14: =DFT!D7 -> 0.34 | H14: =DFT!E7 -> -18.1 | I14: =IF(AND(D14=1,ISNUMBER(E14),E14<=$B$4,F14<=$B$5),1,0) -> 1 | J14: =Green!B6 -> 87.3 | K14: =Green!C6 -> 16.8 | L14: =Green!D6 -> 12.6 | M14: =IF(AND(I14=1,ISNUMBER(J14),J14>=$B$6,K14<=$B$7,L14<=$B$8),1,0) -> 1 | N14: =Composite!D16 -> 0.89 | O14: =Composite!E16 -> 0.92 | P14: =Composite!F16 -> 0.96 | Q14: =Composite!C16 -> 0.94 | R14: =IF(M14=1,RANK(Q14,$Q$12:$Q$59),"") -> 1 | S14: =IF(M14=1,IF(R14<=3,1,0),0) -> 1 | T14: =IF(M14=1,IF(R14=1,1,0),0) -> 1 | U14: =IF(T14=1,"Selected",IF(S14=1,"Top 3",IF(M14=1,"Green screening",IF(I14=1,"DFT stage",IF(D14=1,"Plausibility","AI only"))))) -> Selected
A15: P04 | B15: Route D | C15: 0.92 | D15: 1 | E15: =DFT!B8 -> 22.1 | F15: =DFT!C8 -> 4.54 | G15: =DFT!D8 -> 0.3 | H15: =DFT!E8 -> -15.7 | I15: =IF(AND(D15=1,ISNUMBER(E15),E15<=$B$4,F15<=$B$5),1,0) -> 1 | J15: =Green!B7 -> 79.5 | K15: =Green!C7 -> 22.7 | L15: =Green!D7 -> 16.8 | M15: =IF(AND(I15=1,ISNUMBER(J15),J15>=$B$6,K15<=$B$7,L15<=$B$8),1,0) -> 1 | N15: =Composite!D17 -> 0.85 | O15: =Composite!E17 -> 0.78 | P15: =Composite!F17 -> 0.83 | Q15: =Composite!C17 -> 0.82 | R15: =IF(M15=1,RANK(Q15,$Q$12:$Q$59),"") -> 2 | S15: =IF(M15=1,IF(R15<=3,1,0),0) -> 1 | T15: =IF(M15=1,IF(R15=1,1,0),0) -> 0 | U15: =IF(T15=1,"Selected",IF(S15=1,"Top 3",IF(M15=1,"Green screening",IF(I15=1,"DFT stage",IF(D15=1,"Plausibility","AI only"))))) -> Top 3
A16: P05 | B16: Route E | C16: 0.87 | D16: 1 | E16: =DFT!B9 -> 22.7 | F16: =DFT!C9 -> 4.6 | G16: =DFT!D9 -> 0.25 | H16: =DFT!E9 -> -14.8 | I16: =IF(AND(D16=1,ISNUMBER(E16),E16<=$B$4,F16<=$B$5),1,0) -> 1 | J16: =Green!B8 -> 72.9 | K16: =Green!C8 -> 26.3 | L16: =Green!D8 -> 20.5 | M16: =IF(AND(I16=1,ISNUMBER(J16),J16>=$B$6,K16<=$B$7,L16<=$B$8),1,0) -> 1 | N16: =Composite!D19 -> 0.72 | O16: =Composite!E19 -> 0.7 | P16: =Composite!F19 -> 0.65 | Q16: =Composite!C19 -> 0.69 | R16: =IF(M16=1,RANK(Q16,$Q$12:$Q$59),"") -> 4 | S16: =IF(M16=1,IF(R16<=3,1,0),0) -> 0 | T16: =IF(M16=1,IF(R16=1,1,0),0) -> 0 | U16: =IF(T16=1,"Selected",IF(S16=1,"Top 3",IF(M16=1,"Green screening",IF(I16=1,"DFT stage",IF(D16=1,"Plausibility","AI only"))))) -> Green screening
A17: P06 | B17: Route F | C17: 0.76 | D17: 1 | E17: 21.2 | F17: 4.48 | G17: 0.23 | H17: -11.7 | I17: =IF(AND(D17=1,ISNUMBER(E17),E17<=$B$4,F17<=$B$5),1,0) -> 1 | J17: 80.6 | K17: 21.2 | L17: 16 | M17: =IF(AND(I17=1,ISNUMBER(J17),J17>=$B$6,K17<=$B$7,L17<=$B$8),1,0) -> 1 | N17: 0.7 | O17: 0.66 | P17: 0.6 | Q17: =Composite!$B$4*N17+Composite!$B$5*O17+Composite!$B$6*P17 -> 0.648 | R17: =IF(M17=1,RANK(Q17,$Q$12:$Q$59),"") -> 5 | S17: =IF(M17=1,IF(R17<=3,1,0),0) -> 0 | T17: =IF(M17=1,IF(R17=1,1,0),0) -> 0 | U17: =IF(T17=1,"Selected",IF(S17=1,"Top 3",IF(M17=1,"Green screening",IF(I17=1,"DFT stage",IF(D17=1,"Plausibility","AI only"))))) -> Green screening
A18: P07 | B18: Route G | C18: 0.86 | D18: 1 | E18: 22.9 | F18: 4.49 | G18: 0.32 | H18: -12.9 | I18: =IF(AND(D18=1,ISNUMBER(E18),E18<=$B$4,F18<=$B$5),1,0) -> 1 | J18: 77.3 | K18: 23.4 | L18: 17.8 | M18: =IF(AND(I18=1,ISNUMBER(J18),J18>=$B$6,K18<=$B$7,L18<=$B$8),1,0) -> 1 | N18: 0.62 | O18: 0.58 | P18: 0.55 | Q18: =Composite!$B$4*N18+Composite!$B$5*O18+Composite!$B$6*P18 -> 0.58 | R18: =IF(M18=1,RANK(Q18,$Q$12:$Q$59),"") -> 6 | S18: =IF(M18=1,IF(R18<=3,1,0),0) -> 0 | T18: =IF(M18=1,IF(R18=1,1,0),0) -> 0 | U18: =IF(T18=1,"Selected",IF(S18=1,"Top 3",IF(M18=1,"Green screening",IF(I18=1,"DFT stage",IF(D18=1,"Plausibility","AI only"))))) -> Green screening
A19: P08 | B19: Route H | C19: 0.71 | D19: 1 | E19: 23.4 | F19: 4.65 | G19: 0.24 | H19: -11.4 | I19: =IF(AND(D19=1,ISNUMBER(E19),E19<=$B$4,F19<=$B$5),1,0) -> 1 | J19: 68.9 | K19: 28.7 | L19: 23.2 | M19: =IF(AND(I19=1,ISNUMBER(J19),J19>=$B$6,K19<=$B$7,L19<=$B$8),1,0) -> 1 | N19: 0.58 | O19: 0.52 | P19: 0.5 | Q19: =Composite!$B$4*N19+Composite!$B$5*O19+Composite!$B$6*P19 -> 0.53 | R19: =IF(M19=1,RANK(Q19,$Q$12:$Q$59),"") -> 7 | S19: =IF(M19=1,IF(R19<=3,1,0),0) -> 0 | T19: =IF(M19=1,IF(R19=1,1,0),0) -> 0 | U19: =IF(T19=1,"Selected",IF(S19=1,"Top 3",IF(M19=1,"Green screening",IF(I19=1,"DFT stage",IF(D19=1,"Plausibility","AI only"))))) -> Green screening
A20: P09 | B20: Route I | C20: 0.85 | D20: 1 | E20: 20.6 | F20: 4.66 | G20: 0.18 | H20: -12.3 | I20: =IF(AND(D20=1,ISNUMBER(E20),E20<=$B$4,F20<=$B$5),1,0) -> 1 | J20: 63.2 | K20: 33.1 | L20: 26.4 | M20: =IF(AND(I20=1,ISNUMBER(J20),J20>=$B$6,K20<=$B$7,L20<=$B$8),1,0) -> 1 | N20: 0.5 | O20: 0.47 | P20: 0.44 | Q20: =Composite!$B$4*N20+Composite!$B$5*O20+Composite!$B$6*P20 -> 0.467 | R20: =IF(M20=1,RANK(Q20,$Q$12:$Q$59),"") -> 8 | S20: =IF(M20=1,IF(R20<=3,1,0),0) -> 0 | T20: =IF(M20=1,IF(R20=1,1,0),0) -> 0 | U20: =IF(T20=1,"Selected",IF(S20=1,"Top 3",IF(M20=1,"Green screening",IF(I20=1,"DFT stage",IF(D20=1,"Plausibility","AI only"))))) -> Green screening
A21: P10 | B21: — | C21: 0.76 | D21: 1 | E21: 23.8 | F21: 4.76 | G21: 0.26 | H21: -8.7 | I21: =IF(AND(D21=1,ISNUMBER(E21),E21<=$B$4,F21<=$B$5),1,0) -> 1 | J21: 55.3 | K21: 47.6 | L21: 38.7 | M21: =IF(AND(I21=1,ISNUMBER(J21),J21>=$B$6,K21<=$B$7,L21<=$B$8),1,0) -> 0 | R21: =IF(M21=1,RANK(Q21,$Q$12:$Q$59),"") | S21: =IF(M21=1,IF(R21<=3,1,0),0) -> 0 | T21: =IF(M21=1,IF(R21=1,1,0),0) -> 0 | U21: =IF(T21=1,"Selected",IF(S21=1,"Top 3",IF(M21=1,"Green screening",IF(I21=1,"DFT stage",IF(D21=1,"Plausibility","AI only"))))) -> DFT stage
A22: P11 | B22: — | C22: 0.81 | D22: 1 | E22: 28.1 | F22: 5.02 | G22: 0.17 | H22: -15.1 | I22: =IF(AND(D22=1,ISNUMBER(E22),E22<=$B$4,F22<=$B$5),1,0) -> 1 | J22: 54.7 | K22: 49.8 | L22: 41.8 | M22: =IF(AND(I22=1,ISNUMBER(J22),J22>=$B$6,K22<=$B$7,L22<=$B$8),1,0) -> 0 | R22: =IF(M22=1,RANK(Q22,$Q$12:$Q$59),"") | S22: =IF(M22=1,IF(R22<=3,1,0),0) -> 0 | T22: =IF(M22=1,IF(R22=1,1,0),0) -> 0 | U22: =IF(T22=1,"Selected",IF(S22=1,"Top 3",IF(M22=1,"Green screening",IF(I22=1,"DFT stage",IF(D22=1,"Plausibility","AI only"))))) -> DFT stage
A23: P12 | B23: — | C23: 0.97 | D23: 1 | E23: 30.4 | F23: 5.03 | G23: 0.17 | H23: -8.5 | I23: =IF(AND(D23=1,ISNUMBER(E23),E23<=$B$4,F23<=$B$5),1,0) -> 1 | J23: 57.3 | K23: 42.9 | L23: 34.9 | M23: =IF(AND(I23=1,ISNUMBER(J23),J23>=$B$6,K23<=$B$7,L23<=$B$8),1,0) -> 0 | R23: =IF(M23=1,RANK(Q23,$Q$12:$Q$59),"") | S23: =IF(M23=1,IF(R23<=3,1,0),0) -> 0 | T23: =IF(M23=1,IF(R23=1,1,0),0) -> 0 | U23: =IF(T23=1,"Selected",IF(S23=1,"Top 3",IF(M23=1,"Green screening",IF(I23=1,"DFT stage",IF(D23=1,"Plausibility","AI only"))))) -> DFT stage
A24: P13 | B24: — | C24: 0.83 | D24: 1 | E24: 24.6 | F24: 5.08 | G24: 0.27 | H24: -18.5 | I24: =IF(AND(D24=1,ISNUMBER(E24),E24<=$B$4,F24<=$B$5),1,0) -> 1 | J24: 53.1 | K24: 46.6 | L24: 38.2 | M24: =IF(AND(I24=1,ISNUMBER(J24),J24>=$B$6,K24<=$B$7,L24<=$B$8),1,0) -> 0 | R24: =IF(M24=1,RANK(Q24,$Q$12:$Q$59),"") | S24: =IF(M24=1,IF(R24<=3,1,0),0) -> 0 | T24: =IF(M24=1,IF(R24=1,1,0),0) -> 0 | U24: =IF(T24=1,"Selected",IF(S24=1,"Top 3",IF(M24=1,"Green screening",IF(I24=1,"DFT stage",IF(D24=1,"Plausibility","AI only"))))) -> DFT stage
A25: P14 | B25: — | C25: 0.88 | D25: 1 | E25: 25.1 | F25: 5.1 | G25: 0.33 | H25: -6.5 | I25: =IF(AND(D25=1,ISNUMBER(E25),E25<=$B$4,F25<=$B$5),1,0) -> 1 | J25: 39.4 | K25: 47.5 | L25: 38.3 | M25: =IF(AND(I25=1,ISNUMBER(J25),J25>=$B$6,K25<=$B$7,L25<=$B$8),1,0) -> 0 | R25: =IF(M25=1,RANK(Q25,$Q$12:$Q$59),"") | S25: =IF(M25=1,IF(R25<=3,1,0),0) -> 0 | T25: =IF(M25=1,IF(R25=1,1,0),0) -> 0 | U25: =IF(T25=1,"Selected",IF(S25=1,"Top 3",IF(M25=1,"Green screening",IF(I25=1,"DFT stage",IF(D25=1,"Plausibility","AI only"))))) -> DFT stage
A26: P15 | B26: — | C26: 0.96 | D26: 1 | E26: 31.7 | F26: 5.2 | G26: 0.27 | H26: -11 | I26: =IF(AND(D26=1,ISNUMBER(E26),E26<=$B$4,F26<=$B$5),1,0) -> 1 | J26: 42.7 | K26: 54.2 | L26: 45.3 | M26: =IF(AND(I26=1,ISNUMBER(J26),J26>=$B$6,K26<=$B$7,L26<=$B$8),1,0) -> 0 | R26: =IF(M26=1,RANK(Q26,$Q$12:$Q$59),"") | S26: =IF(M26=1,IF(R26<=3,1,0),0) -> 0 | T26: =IF(M26=1,IF(R26=1,1,0),0) -> 0 | U26: =IF(T26=1,"Selected",IF(S26=1,"Top 3",IF(M26=1,"Green screening",IF(I26=1,"DFT stage",IF(D26=1,"Plausibility","AI only"))))) -> DFT stage
A27: P16 | B27: — | C27: 0.9 | D27: 1 | E27: 26.5 | F27: 5.26 | G27: 0.18 | H27: -18.8 | I27: =IF(AND(D27=1,ISNUMBER(E27),E27<=$B$4,F27<=$B$5),1,0) -> 1 | J27: 46.8 | K27: 49.2 | L27: 42.2 | M27: =IF(AND(I27=1,ISNUMBER(J27),J27>=$B$6,K27<=$B$7,L27<=$B$8),1,0) -> 0 | R27: =IF(M27=1,RANK(Q27,$Q$12:$Q$59),"") | S27: =IF(M27=1,IF(R27<=3,1,0),0) -> 0 | T27: =IF(M27=1,IF(R27=1,1,0),0) -> 0 | U27: =IF(T27=1,"Selected",IF(S27=1,"Top 3",IF(M27=1,"Green screening",IF(I27=1,"DFT stage",IF(D27=1,"Plausibility","AI only"))))) -> DFT stage
A28: P17 | B28: — | C28: 0.75 | D28: 1 | E28: 29.9 | F28: 5.31 | G28: 0.25 | H28: -18.2 | I28: =IF(AND(D28=1,ISNUMBER(E28),E28<=$B$4,F28<=$B$5),1,0) -> 1 | J28: 49.2 | K28: 51.9 | L28: 44.2 | M28: =IF(AND(I28=1,ISNUMBER(J28),J28>=$B$6,K28<=$B$7,L28<=$B$8),1,0) -> 0 | R28: =IF(M28=1,RANK(Q28,$Q$12:$Q$59),"") | S28: =IF(M28=1,IF(R28<=3,1,0),0) -> 0 | T28: =IF(M28=1,IF(R28=1,1,0),0) -> 0 | U28: =IF(T28=1,"Selected",IF(S28=1,"Top 3",IF(M28=1,"Green screening",IF(I28=1,"DFT stage",IF(D28=1,"Plausibility","AI only"))))) -> DFT stage
A29: P18 | B29: — | C29: 0.81 | D29: 1 | E29: 30.6 | F29: 5.36 | G29: 0.18 | H29: -15.9 | I29: =IF(AND(D29=1,ISNUMBER(E29),E29<=$B$4,F29<=$B$5),1,0) -> 1 | J29: 41 | K29: 44.8 | L29: 38.3 | M29: =IF(AND(I29=1,ISNUMBER(J29),J29>=$B$6,K29<=$B$7,L29<=$B$8),1,0) -> 0 | R29: =IF(M29=1,RANK(Q29,$Q$12:$Q$59),"") | S29: =IF(M29=1,IF(R29<=3,1,0),0) -> 0 | T29: =IF(M29=1,IF(R29=1,1,0),0) -> 0 | U29: =IF(T29=1,"Selected",IF(S29=1,"Top 3",IF(M29=1,"Green screening",IF(I29=1,"DFT stage",IF(D29=1,"Plausibility","AI only"))))) -> DFT stage
A30: P19 | B30: — | C30: 0.8 | D30: 1 | E30: 40.5 | F30: 5.74 | G30: 0.17 | H30: 1.2 | I30: =IF(AND(D30=1,ISNUMBER(E30),E30<=$B$4,F30<=$B$5),1,0) -> 0 | M30: =IF(AND(I30=1,ISNUMBER(J30),J30>=$B$6,K30<=$B$7,L30<=$B$8),1,0) -> 0 | R30: =IF(M30=1,RANK(Q30,$Q$12:$Q$59),"") | S30: =IF(M30=1,IF(R30<=3,1,0),0) -> 0 | T30: =IF(M30=1,IF(R30=1,1,0),0) -> 0 | U30: =IF(T30=1,"Selected",IF(S30=1,"Top 3",IF(M30=1,"Green screening",IF(I30=1,"DFT stage",IF(D30=1,"Plausibility","AI only"))))) -> Plausibility
A31: P20 | B31: — | C31: 0.91 | D31: 1 | E31: 42.5 | F31: 6.05 | G31: 0.17 | H31: -6.1 | I31: =IF(AND(D31=1,ISNUMBER(E31),E31<=$B$4,F31<=$B$5),1,0) -> 0 | M31: =IF(AND(I31=1,ISNUMBER(J31),J31>=$B$6,K31<=$B$7,L31<=$B$8),1,0) -> 0 | R31: =IF(M31=1,RANK(Q31,$Q$12:$Q$59),"") | S31: =IF(M31=1,IF(R31<=3,1,0),0) -> 0 | T31: =IF(M31=1,IF(R31=1,1,0),0) -> 0 | U31: =IF(T31=1,"Selected",IF(S31=1,"Top 3",IF(M31=1,"Green screening",IF(I31=1,"DFT stage",IF(D31=1,"Plausibility","AI only"))))) -> Plausibility
A32: P21 | B32: — | C32: 0.9 | D32: 1 | E32: 38.5 | F32: 6.01 | G32: 0.25 | H32: -2.1 | I32: =IF(AND(D32=1,ISNUMBER(E32),E32<=$B$4,F32<=$B$5),1,0) -> 0 | M32: =IF(AND(I32=1,ISNUMBER(J32),J32>=$B$6,K32<=$B$7,L32<=$B$8),1,0) -> 0 | R32: =IF(M32=1,RANK(Q32,$Q$12:$Q$59),"") | S32: =IF(M32=1,IF(R32<=3,1,0),0) -> 0 | T32: =IF(M32=1,IF(R32=1,1,0),0) -> 0 | U32: =IF(T32=1,"Selected",IF(S32=1,"Top 3",IF(M32=1,"Green screening",IF(I32=1,"DFT stage",IF(D32=1,"Plausibility","AI only"))))) -> Plausibility
A33: P22 | B33: — | C33: 0.68 | D33: 1 | E33: 43.3 | F33: 6.25 | G33: 0.15 | H33: -9.9 | I33: =IF(AND(D33=1,ISNUMBER(E33),E33<=$B$4,F33<=$B$5),1,0) -> 0 | M33: =IF(AND(I33=1,ISNUMBER(J33),J33>=$B$6,K33<=$B$7,L33<=$B$8),1,0) -> 0 | R33: =IF(M33=1,RANK(Q33,$Q$12:$Q$59),"") | S33: =IF(M33=1,IF(R33<=3,1,0),0) -> 0 | T33: =IF(M33=1,IF(R33=1,1,0),0) -> 0 | U33: =IF(T33=1,"Selected",IF(S33=1,"Top 3",IF(M33=1,"Green screening",IF(I33=1,"DFT stage",IF(D33=1,"Plausibility","AI only"))))) -> Plausibility
A34: P23 | B34: — | C34: 0.78 | D34: 1 | E34: 36.2 | F34: 5.9 | G34: 0.21 | H34: -9.2 | I34: =IF(AND(D34=1,ISNUMBER(E34),E34<=$B$4,F34<=$B$5),1,0) -> 0 | M34: =IF(AND(I34=1,ISNUMBER(J34),J34>=$B$6,K34<=$B$7,L34<=$B$8),1,0) -> 0 | R34: =IF(M34=1,RANK(Q34,$Q$12:$Q$59),"") | S34: =IF(M34=1,IF(R34<=3,1,0),0) -> 0 | T34: =IF(M34=1,IF(R34=1,1,0),0) -> 0 | U34: =IF(T34=1,"Selected",IF(S34=1,"Top 3",IF(M34=1,"Green screening",IF(I34=1,"DFT stage",IF(D34=1,"Plausibility","AI only"))))) -> Plausibility
A35: P24 | B35: — | C35: 0.72 | D35: 1 | E35: 39.7 | F35: 6.25 | G35: 0.24 | H35: -3.8 | I35: =IF(AND(D35=1,ISNUMBER(E35),E35<=$B$4,F35<=$B$5),1,0) -> 0 | M35: =IF(AND(I35=1,ISNUMBER(J35),J35>=$B$6,K35<=$B$7,L35<=$B$8),1,0) -> 0 | R35: =IF(M35=1,RANK(Q35,$Q$12:$Q$59),"") | S35: =IF(M35=1,IF(R35<=3,1,0),0) -> 0 | T35: =IF(M35=1,IF(R35=1,1,0),0) -> 0 | U35: =IF(T35=1,"Selected",IF(S35=1,"Top 3",IF(M35=1,"Green screening",IF(I35=1,"DFT stage",IF(D35=1,"Plausibility","AI only"))))) -> Plausibility
A36: P25 | B36: — | C36: 0.65 | D36: 1 | E36: 37.7 | F36: 5.72 | G36: 0.24 | H36: -5.5 | I36: =IF(AND(D36=1,ISNUMBER(E36),E36<=$B$4,F36<=$B$5),1,0) -> 0 | M36: =IF(AND(I36=1,ISNUMBER(J36),J36>=$B$6,K36<=$B$7,L36<=$B$8),1,0) -> 0 | R36: =IF(M36=1,RANK(Q36,$Q$12:$Q$59),"") | S36: =IF(M36=1,IF(R36<=3,1,0),0) -> 0 | T36: =IF(M36=1,IF(R36=1,1,0),0) -> 0 | U36: =IF(T36=1,"Selected",IF(S36=1,"Top 3",IF(M36=1,"Green screening",IF(I36=1,"DFT stage",IF(D36=1,"Plausibility","AI only"))))) -> Plausibility
A37: P26 | B37: — | C37: 0.83 | D37: 1 | E37: 39.8 | F37: 6.34 | G37: 0.11 | H37: -6.4 | I37: =IF(AND(D37=1,ISNUMBER(E37),E37<=$B$4,F37<=$B$5),1,0) -> 0 | M37: =IF(AND(I37=1,ISNUMBER(J37),J37>=$B$6,K37<=$B$7,L37<=$B$8),1,0) -> 0 | R37: =IF(M37=1,RANK(Q37,$Q$12:$Q$59),"") | S37: =IF(M37=1,IF(R37<=3,1,0),0) -> 0 | T37: =IF(M37=1,IF(R37=1,1,0),0) -> 0 | U37: =IF(T37=1,"Selected",IF(S37=1,"Top 3",IF(M37=1,"Green screening",IF(I37=1,"DFT stage",IF(D37=1,"Plausibility","AI only"))))) -> Plausibility
A38: P27 | B38: — | C38: 0.85 | D38: 1 | E38: 38.4 | F38: 6.21 | G38: 0.11 | H38: -10 | I38: =IF(AND(D38=1,ISNUMBER(E38),E38<=$B$4,F38<=$B$5),1,0) -> 0 | M38: =IF(AND(I38=1,ISNUMBER(J38),J38>=$B$6,K38<=$B$7,L38<=$B$8),1,0) -> 0 | R38: =IF(M38=1,RANK(Q38,$Q$12:$Q$59),"") | S38: =IF(M38=1,IF(R38<=3,1,0),0) -> 0 | T38: =IF(M38=1,IF(R38=1,1,0),0) -> 0 | U38: =IF(T38=1,"Selected",IF(S38=1,"Top 3",IF(M38=1,"Green screening",IF(I38=1,"DFT stage",IF(D38=1,"Plausibility","AI only"))))) -> Plausibility
A39: P28 | B39: — | C39: 0.83 | D39: 1 | E39: 43.8 | F39: 6.33 | G39: 0.12 | H39: -9.6 | I39: =IF(AND(D39=1,ISNUMBER(E39),E39<=$B$4,F39<=$B$5),1,0) -> 0 | M39: =IF(AND(I39=1,ISNUMBER(J39),J39>=$B$6,K39<=$B$7,L39<=$B$8),1,0) -> 0 | R39: =IF(M39=1,RANK(Q39,$Q$12:$Q$59),"") | S39: =IF(M39=1,IF(R39<=3,1,0),0) -> 0 | T39: =IF(M39=1,IF(R39=1,1,0),0) -> 0 | U39: =IF(T39=1,"Selected",IF(S39=1,"Top 3",IF(M39=1,"Green screening",IF(I39=1,"DFT stage",IF(D39=1,"Plausibility","AI only"))))) -> Plausibility
A40: P29 | B40: — | C40: 0.9 | D40: 1 | E40: 36.1 | F40: 5.78 | G40: 0.22 | H40: -11.9 | I40: =IF(AND(D40=1,ISNUMBER(E40),E40<=$B$4,F40<=$B$5),1,0) -> 0 | M40: =IF(AND(I40=1,ISNUMBER(J40),J40>=$B$6,K40<=$B$7,L40<=$B$8),1,0) -> 0 | R40: =IF(M40=1,RANK(Q40,$Q$12:$Q$59),"") | S40: =IF(M40=1,IF(R40<=3,1,0),0) -> 0 | T40: =IF(M40=1,IF(R40=1,1,0),0) -> 0 | U40: =IF(T40=1,"Selected",IF(S40=1,"Top 3",IF(M40=1,"Green screening",IF(I40=1,"DFT stage",IF(D40=1,"Plausibility","AI only"))))) -> Plausibility
A41: P30 | B41: — | C41: 0.85 | D41: 1 | E41: 40.4 | F41: 6.07 | G41: 0.13 | H41: -5.2 | I41: =IF(AND(D41=1,ISNUMBER(E41),E41<=$B$4,F41<=$B$5),1,0) -> 0 | M41: =IF(AND(I41=1,ISNUMBER(J41),J41>=$B$6,K41<=$B$7,L41<=$B$8),1,0) -> 0 | R41: =IF(M41=1,RANK(Q41,$Q$12:$Q$59),"") | S41: =IF(M41=1,IF(R41<=3,1,0),0) -> 0 | T41: =IF(M41=1,IF(R41=1,1,0),0) -> 0 | U41: =IF(T41=1,"Selected",IF(S41=1,"Top 3",IF(M41=1,"Green screening",IF(I41=1,"DFT stage",IF(D41=1,"Plausibility","AI only"))))) -> Plausibility
A42: P31 | B42: — | C42: 0.92 | D42: 1 | E42: 42.5 | F42: 5.8 | G42: 0.12 | H42: -6.4 | I42: =IF(AND(D42=1,ISNUMBER(E42),E42<=$B$4,F42<=$B$5),1,0) -> 0 | M42: =IF(AND(I42=1,ISNUMBER(J42),J42>=$B$6,K42<=$B$7,L42<=$B$8),1,0) -> 0 | R42: =IF(M42=1,RANK(Q42,$Q$12:$Q$59),"") | S42: =IF(M42=1,IF(R42<=3,1,0),0) -> 0 | T42: =IF(M42=1,IF(R42=1,1,0),0) -> 0 | U42: =IF(T42=1,"Selected",IF(S42=1,"Top 3",IF(M42=1,"Green screening",IF(I42=1,"DFT stage",IF(D42=1,"Plausibility","AI only"))))) -> Plausibility
A43: P32 | B43: — | C43: 0.61 | D43: 0 | I43: =IF(AND(D43=1,ISNUMBER(E43),E43<=$B$4,F43<=$B$5),1,0) -> 0 | M43: =IF(AND(I43=1,ISNUMBER(J43),J43>=$B$6,K43<=$B$7,L43<=$B$8),1,0) -> 0 | R43: =IF(M43=1,RANK(Q43,$Q$12:$Q$59),"") | S43: =IF(M43=1,IF(R43<=3,1,0),0) -> 0 | T43: =IF(M43=1,IF(R43=1,1,0),0) -> 0 | U43: =IF(T43=1,"Selected",IF(S43=1,"Top 3",IF(M43=1,"Green screening",IF(I43=1,"DFT stage",IF(D43=1,"Plausibility","AI only"))))) -> AI only
...

Sheet Pathways_Check
A3: Statistic | B3: Recomputed from Pathways_48 | C3: Paper value | D3: Match (rounded to 2 decimals) | E3: Paper source
A4: Pathways generated by AI | B4: =COUNTA(Pathways_48!A12:A59) -> 48 | C4: =Funnel!C4 -> 48 | D4: =IF(ISNUMBER(B4),IF(ROUND(B4,2)=ROUND(C4,2),"OK","CHECK"),IF(B4=C4,"OK","CHECK")) -> OK | E4: Table 14
A5: Pathways after plausibility filter | B5: =SUM(Pathways_48!D12:D59) -> 31 | C5: =Funnel!C5 -> 31 | D5: =IF(ISNUMBER(B5),IF(ROUND(B5,2)=ROUND(C5,2),"OK","CHECK"),IF(B5=C5,"OK","CHECK")) -> OK | E5: Table 14
A6: Pathways after DFT stage | B6: =SUM(Pathways_48!I12:I59) -> 18 | C6: =Funnel!C6 -> 18 | D6: =IF(ISNUMBER(B6),IF(ROUND(B6,2)=ROUND(C6,2),"OK","CHECK"),IF(B6=C6,"OK","CHECK")) -> OK | E6: Table 14
A7: Pathways after green screening | B7: =SUM(Pathways_48!M12:M59) -> 9 | C7: =Funnel!C7 -> 9 | D7: =IF(ISNUMBER(B7),IF(ROUND(B7,2)=ROUND(C7,2),"OK","CHECK"),IF(B7=C7,"OK","CHECK")) -> OK | E7: Table 14
A8: Pathways in top ranking group | B8: =SUM(Pathways_48!S12:S59) -> 3 | C8: =Funnel!C8 -> 3 | D8: =IF(ISNUMBER(B8),IF(ROUND(B8,2)=ROUND(C8,2),"OK","CHECK"),IF(B8=C8,"OK","CHECK")) -> OK | E8: Table 14
A9: Final selected pathways | B9: =SUM(Pathways_48!T12:T59) -> 1 | C9: =Funnel!C9 -> 1 | D9: =IF(ISNUMBER(B9),IF(ROUND(B9,2)=ROUND(C9,2),"OK","CHECK"),IF(B9=C9,"OK","CHECK")) -> OK | E9: Table 14
A10: AI confidence BEFORE filtering – mean | B10: =AVERAGE(Pathways_48!C12:C59) -> 0.79104167 | C10: =AI_Confidence!B5 -> 0.79 | D10: =IF(ISNUMBER(B10),IF(ROUND(B10,2)=ROUND(C10,2),"OK","CHECK"),IF(B10=C10,"OK","CHECK")) -> OK | E10: Fig. 7B
A11: AI confidence BEFORE – median | B11: =MEDIAN(Pathways_48!C12:C59) -> 0.81 | C11: =AI_Confidence!B6 -> 0.81 | D11: =IF(ISNUMBER(B11),IF(ROUND(B11,2)=ROUND(C11,2),"OK","CHECK"),IF(B11=C11,"OK","CHECK")) -> OK | E11: Fig. 7B
A12: AI confidence BEFORE – SD (sample) | B12: =STDEV(Pathways_48!C12:C59) -> 0.10727256 | C12: =AI_Confidence!B7 -> 0.11 | D12: =IF(ISNUMBER(B12),IF(ROUND(B12,2)=ROUND(C12,2),"OK","CHECK"),IF(B12=C12,"OK","CHECK")) -> OK | E12: Fig. 7B
A13: AI confidence BEFORE – min | B13: =MIN(Pathways_48!C12:C59) -> 0.61 | C13: =AI_Confidence!B8 -> 0.61 | D13: =IF(ISNUMBER(B13),IF(ROUND(B13,2)=ROUND(C13,2),"OK","CHECK"),IF(B13=C13,"OK","CHECK")) -> OK | E13: Fig. 7B
A14: AI confidence BEFORE – max | B14: =MAX(Pathways_48!C12:C59) -> 0.97 | C14: =AI_Confidence!B9 -> 0.97 | D14: =IF(ISNUMBER(B14),IF(ROUND(B14,2)=ROUND(C14,2),"OK","CHECK"),IF(B14=C14,"OK","CHECK")) -> OK | E14: Fig. 7B
A15: Pathways with confidence > 0.80 BEFORE | B15: =COUNTIF(Pathways_48!C12:C59,">0.8") -> 28 | C15: =AI_Confidence!B10 -> 28 | D15: =IF(ISNUMBER(B15),IF(ROUND(B15,2)=ROUND(C15,2),"OK","CHECK"),IF(B15=C15,"OK","CHECK")) -> OK | E15: Fig. 7B
A16: AI confidence AFTER filtering – mean | B16: =AVERAGE(Pathways_48!C12:C42) -> 0.8383871 | C16: =AI_Confidence!C5 -> 0.84 | D16: =IF(ISNUMBER(B16),IF(ROUND(B16,2)=ROUND(C16,2),"OK","CHECK"),IF(B16=C16,"OK","CHECK")) -> OK | E16: Table 15 / Fig. 7B
A17: AI confidence AFTER – median | B17: =MEDIAN(Pathways_48!C12:C42) -> 0.85 | C17: =AI_Confidence!C6 -> 0.85 | D17: =IF(ISNUMBER(B17),IF(ROUND(B17,2)=ROUND(C17,2),"OK","CHECK"),IF(B17=C17,"OK","CHECK")) -> OK | E17: Fig. 7B
A18: AI confidence AFTER – SD (sample) | B18: =STDEV(Pathways_48!C12:C42) -> 0.082869245 | C18: =AI_Confidence!C7 -> 0.08 | D18: =IF(ISNUMBER(B18),IF(ROUND(B18,2)=ROUND(C18,2),"OK","CHECK"),IF(B18=C18,"OK","CHECK")) -> OK | E18: Table 15 / Fig. 7B
A19: AI confidence AFTER – min | B19: =MIN(Pathways_48!C12:C42) -> 0.65 | C19: =AI_Confidence!C8 -> 0.65 | D19: =IF(ISNUMBER(B19),IF(ROUND(B19,2)=ROUND(C19,2),"OK","CHECK"),IF(B19=C19,"OK","CHECK")) -> OK | E19: Fig. 7B (Table 15 text says 0.61)
A20: AI confidence AFTER – max | B20: =MAX(Pathways_48!C12:C42) -> 0.97 | C20: =AI_Confidence!C9 -> 0.97 | D20: =IF(ISNUMBER(B20),IF(ROUND(B20,2)=ROUND(C20,2),"OK","CHECK"),IF(B20=C20,"OK","CHECK")) -> OK | E20: Table 15 / Fig. 7B
A21: Pathways with confidence > 0.80 AFTER | B21: =COUNTIF(Pathways_48!C12:C42,">0.8") -> 22 | C21: =AI_Confidence!C10 -> 22 | D21: =IF(ISNUMBER(B21),IF(ROUND(B21,2)=ROUND(C21,2),"OK","CHECK"),IF(B21=C21,"OK","CHECK")) -> OK | E21: Table 15
A22: DFT survivors – min ΔG‡ (kcal/mol) | B22: =MIN(Pathways_48!E12:E29) -> 18.6 | C22: =DFT!C13 -> 18.6 | D22: =IF(ISNUMBER(B22),IF(ROUND(B22,2)=ROUND(C22,2),"OK","CHECK"),IF(B22=C22,"OK","CHECK")) -> OK | E22: Results: 18.6–33.8
A23: DFT survivors – max ΔG‡ (kcal/mol) | B23: =MAX(Pathways_48!E12:E29) -> 33.8 | C23: =DFT!C14 -> 33.8 | D23: =IF(ISNUMBER(B23),IF(ROUND(B23,2)=ROUND(C23,2),"OK","CHECK"),IF(B23=C23,"OK","CHECK")) -> OK | E23: Results: 18.6–33.8
A24: DFT survivors – min HOMO–LUMO gap (eV) | B24: =MIN(Pathways_48!F12:F29) -> 4.28 | C24: =DFT!C15 -> 4.28 | D24: =IF(ISNUMBER(B24),IF(ROUND(B24,2)=ROUND(C24,2),"OK","CHECK"),IF(B24=C24,"OK","CHECK")) -> OK | E24: Results: 4.28–5.61
A25: DFT survivors – max HOMO–LUMO gap (eV) | B25: =MAX(Pathways_48!F12:F29) -> 5.61 | C25: =DFT!C16 -> 5.61 | D25: =IF(ISNUMBER(B25),IF(ROUND(B25,2)=ROUND(C25,2),"OK","CHECK"),IF(B25=C25,"OK","CHECK")) -> OK | E25: Results: 4.28–5.61
A26: DFT survivors – R² (gap vs ΔG‡) | B26: =RSQ(Pathways_48!E12:E29,Pathways_48!F12:F29) -> 0.8198016 | C26: =DFT!C18 -> 0.82 | D26: =IF(ISNUMBER(B26),IF(ROUND(B26,2)=ROUND(C26,2),"OK","CHECK"),IF(B26=C26,"OK","CHECK")) -> OK | E26: Fig. 8A
A27: DFT survivors – |Pearson r| (gap vs ΔG‡) | B27: =ABS(CORREL(Pathways_48!F12:F29,Pathways_48!E12:E29)) -> 0.90542896 | C27: =ABS(DFT!C17) -> 0.91 | D27: =IF(ISNUMBER(B27),IF(ROUND(B27,2)=ROUND(C27,2),"OK","CHECK"),IF(B27=C27,"OK","CHECK")) -> OK | E27: Fig. 8A (paper prints r = −0.91; reconstructed data have r > 0, see Inconsistencies)
A28: DFT survivors – all ΔGrxn negative? | B28: =IF(MAX(Pathways_48!H12:H29)<0,"Yes","No") -> Yes | C28: Yes | D28: =IF(ISNUMBER(B28),IF(ROUND(B28,2)=ROUND(C28,2),"OK","CHECK"),IF(B28=C28,"OK","CHECK")) -> OK | E28: Results
A29: Highest f⁺ among survivors | B29: =MAX(Pathways_48!G12:G29) -> 0.34 | C29: =DFT!D7 -> 0.34 | D29: =IF(ISNUMBER(B29),IF(ROUND(B29,2)=ROUND(C29,2),"OK","CHECK"),IF(B29=C29,"OK","CHECK")) -> OK | E29: Route C, 0.34
A30: Green survivors – max atom economy (%) | B30: =MAX(Pathways_48!J12:J20) -> 87.3 | C30: =Green!C29 -> 87.3 | D30: =IF(ISNUMBER(B30),IF(ROUND(B30,2)=ROUND(C30,2),"OK","CHECK"),IF(B30=C30,"OK","CHECK")) -> OK | E30: Results: 87.3
A31: Green survivors – min atom economy (%) | B31: =MIN(Pathways_48!J12:J20) -> 58.4 | C31: =Green!C30 -> 58.4 | D31: =IF(ISNUMBER(B31),IF(ROUND(B31,2)=ROUND(C31,2),"OK","CHECK"),IF(B31=C31,"OK","CHECK")) -> OK | E31: Results: 58.4
A32: Green survivors – min PMI | B32: =MIN(Pathways_48!K12:K20) -> 16.8 | C32: =Green!C31 -> 16.8 | D32: =IF(ISNUMBER(B32),IF(ROUND(B32,2)=ROUND(C32,2),"OK","CHECK"),IF(B32=C32,"OK","CHECK")) -> OK | E32: Results: 16.8
A33: Green survivors – max PMI | B33: =MAX(Pathways_48!K12:K20) -> 38.4 | C33: =Green!C32 -> 38.4 | D33: =IF(ISNUMBER(B33),IF(ROUND(B33,2)=ROUND(C33,2),"OK","CHECK"),IF(B33=C33,"OK","CHECK")) -> OK | E33: Results: 38.4
A34: Green survivors – min E-factor | B34: =MIN(Pathways_48!L12:L20) -> 12.6 | C34: =Green!D6 -> 12.6 | D34: =IF(ISNUMBER(B34),IF(ROUND(B34,2)=ROUND(C34,2),"OK","CHECK"),IF(B34=C34,"OK","CHECK")) -> OK | E34: Route C: 12.6
A35: Green survivors – max E-factor | B35: =MAX(Pathways_48!L12:L20) -> 31.2 | C35: =Green!D4 -> 31.2 | D35: =IF(ISNUMBER(B35),IF(ROUND(B35,2)=ROUND(C35,2),"OK","CHECK"),IF(B35=C35,"OK","CHECK")) -> OK | E35: Route A: 31.2
A36: Composite score – min of 9 routes | B36: =MIN(Pathways_48!Q12:Q20) -> 0.41 | C36: =Composite!C22 -> 0.41 | D36: =IF(ISNUMBER(B36),IF(ROUND(B36,2)=ROUND(C36,2),"OK","CHECK"),IF(B36=C36,"OK","CHECK")) -> OK | E36: Results: 0.41
A37: Composite score – max of 9 routes | B37: =MAX(Pathways_48!Q12:Q20) -> 0.94 | C37: =Composite!E22 -> 0.94 | D37: =IF(ISNUMBER(B37),IF(ROUND(B37,2)=ROUND(C37,2),"OK","CHECK"),IF(B37=C37,"OK","CHECK")) -> OK | E37: Results: 0.94
A38: Final selected route is Route C? | B38: =IF(Pathways_48!T14=1,"Yes","No") -> Yes | C38: Yes | D38: =IF(ISNUMBER(B38),IF(ROUND(B38,2)=ROUND(C38,2),"OK","CHECK"),IF(B38=C38,"OK","CHECK")) -> OK | E38: Table 18
A39: Top-3 group is Routes C, D, B? | B39: =IF(AND(Pathways_48!S14=1,Pathways_48!S15=1,Pathways_48!S13=1,SUM(Pathways_48!S12:S59)=3),"Yes","No") -> Yes | C39: Yes | D39: =IF(ISNUMBER(B39),IF(ROUND(B39,2)=ROUND(C39,2),"OK","CHECK"),IF(B39=C39,"OK","CHECK")) -> OK | E39: Table 18
A41: Overall | D41: =IF(COUNTIF(D4:D39,"OK")=ROWS(D4:D39),"ALL MATCH","CHECK") -> ALL MATCH

Sheet Qualitative_Tables
A3: Table 1 – DFT protocol
A4: Computational parameter | B4: Description
A5: Electronic structure method | B5: Kohn–Sham Density Functional Theory (DFT)
A6: Exchange–correlation functional | B6: B3LYP hybrid functional
A7: Basis set | B7: 6-31G(d)
A8: Geometry optimization | B8: Full geometry optimization without symmetry constraints
A9: Electronic descriptors calculated | B9: HOMO energy, LUMO energy, HOMO–LUMO gap (ΔEHL), condensed Fukui indices
A10: Primary objective | B10: Comparative evaluation of electronic reactivity among candidate synthetic pathways
A11: Role within the framework | B11: Descriptor generation for multi-objective pathway ranking
A12: Relative comparison | B12: All candidate pathways evaluated using an identical computational protocol
A13: Output used in subsequent analysis | B13: Descriptors integrated with AI-derived pathway predictions and green chemistry metrics
A14: Scope of interpretation | B14: Relative mechanistic assessment, not quantitative kinetics
A16: Table 2 – Quantum descriptors
A17: Descriptor | B17: Symbol | C17: Physical meaning | D17: Role in route ranking
A18: HOMO energy | B18: EHOMO | C18: Electron donation ability | D18: Reactivity assessment
A19: LUMO energy | B19: ELUMO | C19: Electron acceptance ability | D19: Electrophilic behavior
A20: HOMO–LUMO gap | B20: ΔEHL | C20: Electronic stability | D20: Relative reaction feasibility
A21: Fukui index (f⁺) | B21: f⁺ | C21: Nucleophilic susceptibility | D21: Identification of reactive sites
A22: Fukui index (f⁻) | B22: f⁻ | C22: Electrophilic susceptibility | D22: Identification of reactive sites
A23: Chemical hardness | B23: η | C23: Resistance to charge transfer | D23: Molecular stability
A24: Chemical potential | B24: µ | C24: Electron escaping tendency | D24: Electronic characterization
A25: Electrophilicity index | B25: ω | C25: Global electrophilic character | D25: Pathway prioritization
A27: Table 3 – Green chemistry metrics
A28: Metric | B28: Definition | C28: Interpretation | D28: Optimization objective
A29: Atom economy | B29: Fraction of reactant atoms incorporated into the product | C29: Higher = more efficient atom utilization | D29: Maximize
A30: E-factor | B30: Mass of waste generated per unit product | C30: Lower = reduced waste | D30: Minimize
A31: Process mass intensity (PMI) | B31: Total material input divided by product mass | C31: Lower = greater material efficiency | D31: Minimize
A32: Reaction mass efficiency | B32: Product mass relative to reactant mass | C32: Higher = improved process efficiency | D32: Maximize
A34: Table 4 – AI module configuration
A35: Component | B35: Description
A36: Molecular representation | B36: Canonical SMILES
A37: Prediction strategy | B37: Transformer-based retrosynthesis
A38: Search strategy | B38: Beam Search
A39: Output | B39: Candidate pathways
A40: Confidence | B40: Relative ranking
A41: Role | B41: Hypothesis generation
A43: Table 5 – Workflow stages
A44: Stage | B44: Input | C44: Output
A45: AI | B45: Target molecule | C45: Candidate routes
A46: DFT | B46: Structures | C46: Electronic descriptors
...
